Workbook

Sheet Sheet1
A2: 交易时间
B3: 1000 | C3: 新高 | D3: 新低 | G3: 300 | H3: 新高 | I3: 新低
A4: 44095 | C4: 43 | D4: 36 | H4: 12 | I4: 17
A5: 44096 | C5: 14 | D5: 211 | H5: 5 | I5: 57
A6: 44097 | B6: -94 | C6: 26 | D6: 118 | E6: 6862.97 | G6: -32.666667 | H6: 7 | I6: 48
A7: 44098 | B7: -256.66667 | C7: 8 | D7: 489 | E7: 6675.15 | G7: -70.666667 | H7: 0 | I7: 119
A8: 44099 | B8: -329 | C8: 8 | D8: 422 | E8: 6634.39 | G8: -85.333333 | H8: 4 | I8: 100
A9: 44102 | B9: -466.66667 | C9: 17 | D9: 522 | E9: 6550.37 | G9: -97.333333 | H9: 3 | I9: 80
A10: 44103 | B10: -350 | C10: 23 | D10: 154 | E10: 6621.03 | G10: -71.666667 | H10: 5 | I10: 47
A11: 44104 | B11: -292 | C11: 21 | D11: 261 | E11: 6617.16 | G11: -61.333333 | H11: 9 | I11: 74
A12: 44113 | B12: -98 | C12: 85 | D12: 8 | E12: 6822.36 | G12: -26.666667 | H12: 34 | I12: 7
A13: 44116 | B13: 8 | C13: 190 | D13: 3 | E13: 7036.28 | G13: 14.333333 | H13: 83 | I13: 2
A14: 44117 | B14: 138 | C14: 157 | D14: 7 | E14: 7053.87 | G14: 56.333333 | H14: 64 | I14: 3
A15: 44118 | B15: 145.33333 | C15: 120 | D15: 21 | E15: 6988.61 | G15: 57.333333 | H15: 41 | I15: 11
A16: 44119 | B16: 97.333333 | C16: 88 | D16: 45 | E16: 6926.85 | G16: 37 | H16: 36 | I16: 16
A17: 44120 | B17: 52 | C17: 77 | D17: 63 | E17: 6906.39 | G17: 22.666667 | H17: 34 | I17: 16
... A1150: 45827 | B1150: -115.33333 | C1150: 52 | D1150: 320 | E1150: 6048.22 | G1150: -26.333333 | H1150: 16 | I1150: 95
A1151: 45828 | B1151: -199.33333 | E1151: 5999.59 | G1151: -41 | H1151: 27 | I1151: 68
A1152: 45831 | B1152: -169.33333 | E1152: 6078.22 | G1152: -44.333333 | H1152: 35 | I1152: 48
A1153: 45832 | B1153: -26.333333 | E1153: 6194.67 | G1153: -1.6666667 | H1153: 57 | I1153: 8
A1154: 45833 | B1154: 143.33333 | E1154: 6276.16 | G1154: 42 | H1154: 94 | I1154: 4
A1155: 45834 | B1155: 181 | E1155: 6247.79 | G1155: 59.333333 | H1155: 47 | I1155: 8
A1156: 45835 | B1156: 207 | E1156: 6276.94 | G1156: 54.333333 | H1156: 46 | I1156: 12
A1157: 45838 | B1157: 185.33333 | E1157: 6356.18 | G1157: 41 | H1157: 57 | I1157: 7
A1158: 45839 | B1158: 174.66667 | E1158: 6373.77 | G1158: 40.666667 | H1158: 43 | I1158: 5
A1159: 45840 | B1159: 133 | E1159: 6309.48 | G1159: 46.333333 | H1159: 60 | I1159: 9
A1160: 45841 | B1160: 92.333333 | E1160: 6342.64 | G1160: 46.333333 | H1160: 59 | I1160: 9
A1161: 45842 | B1161: 95.333333 | E1161: 6312.2 | G1161: 47 | H1161: 47 | I1161: 7
A1162: 45845 | B1162: 129.33333 | E1162: 6327.14 | G1162: 39.666667 | H1162: 45 | I1162: 16
... A1212: 45915 | B1212: 44.333333 | E1212: 7415.57 | G1212: 1 | H1212: 23 | I1212: 42
A1213: 45916 | B1213: 51 | E1213: 7483.63 | G1213: =AVERAGE(H1211:H1213)-AVERAGE(I1211:I1213) -> -19 | H1213: 22 | I1213: 54
A1214: 45917 | B1214: 6.6666667 | E1214: 7554.81
A1215: 45918 | B1215: -54.666667 | E1215: 7476.4
A1216: 45919 | B1216: -130.66667 | E1216: 7438.19
A1217: 45922 | B1217: -179.66667 | E1217: 7489.48
A1218: 45923 | B1218: 0 | E1218: 7408.07
A1219: 45924 | B1219: 0 | E1219: 7507.58

Sheet 测算
A1: 交易时间 | B1: 开盘价 | C1: 最高价 | D1: 最低价 | E1: 收盘价 | I1: 成交额 | J1: 5 | K1: 20
A2: 42334 | B2: 10745.06 | C2: 10772.62 | D2: 10595.1 | E2: 10620.83 | I2: 376940830720
A3: 42335 | B3: 10560.39 | C3: 10619.71 | D3: 9859.02 | E3: 9933.5 | I3: 372029538304
A4: 42338 | B4: 9935.4 | C4: 10058.66 | D4: 9406.73 | E4: 10001.19 | I4: 321899188224
A5: 42339 | B5: 9985.79 | C5: 10101.51 | D5: 9832.26 | E5: 9955.21 | I5: 271316594688
A6: 42340 | B6: 9928.27 | C6: 9954.86 | D6: 9506.1 | E6: 9822.06 | I6: 236802535424
A7: 42341 | B7: 9833.3 | C7: 10103.49 | D7: 9832.95 | E7: 10102.89 | I7: 240931471360
A8: 42342 | B8: 10073.67 | C8: 10199.95 | D8: 9996.29 | E8: 10081.57 | I8: 268457361408
A9: 42345 | B9: 10105.79 | C9: 10238.79 | D9: 10038.58 | E9: 10238.02 | I9: 258635124736
A10: 42346 | B10: 10189.87 | C10: 10210.75 | D10: 10022.62 | E10: 10057.74 | I10: 280221765632
A11: 42347 | B11: 10002.73 | C11: 10111.56 | D11: 9945.79 | E11: 10034.19 | I11: 254279454720
A12: 42348 | B12: 10024.19 | C12: 10145.99 | D12: 10008.74 | E12: 10035.45 | I12: 256497684480
A13: 42349 | B13: 10003.76 | C13: 10043.54 | D13: 9915.11 | E13: 9946.12 | I13: 221143658496
... A22: 42362 | B22: 10600.47 | C22: 10662.43 | D22: 10413.92 | E22: 10633.19 | I22: 230327783424
A23: 42363 | B23: 10651.66 | C23: 10760.15 | D23: 10645.44 | E23: 10726.99 | I23: 219758198784 | J23: 2.5883043e+11
A24: 42366 | B24: 10765.91 | C24: 10859.83 | D24: 10515.36 | E24: 10515.36 | I24: 298902507520 | J24: 2.6295248e+11
A25: 42367 | B25: 10499.5 | C25: 10654.42 | D25: 10406.06 | E25: 10653.71 | I25: 228954329088 | J25: 2.4920501e+11
A26: 42368 | B26: 10678.11 | C26: 10813.02 | D26: 10661.28 | E26: 10806.7 | I26: 256185892864 | J26: 2.6134758e+11
A27: 42369 | B27: 10810.35 | C27: 10839.05 | D27: 10614.38 | E27: 10614.38 | I27: 240733024256 | J27: 241957748736
A28: 42373 | B28: 10598.27 | C28: 10602.65 | D28: 9694.63 | E28: 9694.84 | I28: 196597043200 | J28: 2.3117199e+11
A29: 42374 | B29: 9140.67 | C29: 9680.16 | D29: 9084.87 | E29: 9452.04 | I29: 265746817024 | J29: 2.3435896e+11
A30: 42375 | B30: 9511.73 | C30: 9710.12 | D30: 9404.07 | E30: 9709.57 | I30: 227283116032 | J30: 229875658752
A31: 42376 | B31: 9511.14 | C31: 9511.14 | D31: 8850.15 | E31: 8856.49 | I31: 57536623616 | J31: 1.8352219e+11
A32: 42377 | B32: 9049.77 | C32: 9141.57 | D32: 8404.51 | E32: 8876.25 | I32: 230862790656 | J32: 171894176768
A33: 42380 | B33: 8651.33 | C33: 8754.36 | D33: 8203.43 | E33: 8205.12 | I33: 194711633920 | J33: 161037016064
A34: 42381 | B34: 8164.34 | C34: 8304.14 | D34: 7968.75 | E34: 8187.96 | I34: 169839431680 | J34: 1.9847129e+11
... A59: 42423 | B59: 8414.67 | C59: 8437.16 | D59: 8230.98 | E59: 8357.36 | I59: 192375009280 | J59: 184889352192
A60: 42424 | B60: 8316.83 | C60: 8399.43 | D60: 8161 | E60: 8364.66 | I60: 196294406144 | J60: 1.9408099e+11 | K60: 1.5387541e+11
A61: 42425 | B61: 8340.46 | C61: 8340.59 | D61: 7673.22 | E61: 7702.59 | I61: 214208675840 | J61: 2.0095936e+11 | K61: 1.5580609e+11
A62: 42426 | B62: 7750.74 | C62: 7799.3 | D62: 7487.27 | E62: 7666.82 | I62: 158808006656 | J62: 189770362880 | K62: 1.5644824e+11
A63: 42429 | B63: 7614.16 | C63: 7614.16 | D63: 7113.07 | E63: 7183.68 | I63: 138384515072 | J63: 170467065856 | K63: 1.5633751e+11
A64: 42430 | B64: 7183.11 | C64: 7402.31 | D64: 7038.61 | E64: 7345.09 | I64: 144811421696 | J64: 147334647808 | K64: 1.5529901e+11
A65: 42431 | B65: 7324.49 | C65: 7724.3 | D65: 7323.37 | E65: 7711.89 | I65: 183328415744 | J65: 155508117504 | K65: 1.5649135e+11
A66: 42432 | B66: 7711.3 | C66: 7875.95 | D66: 7693.9 | E66: 7727.16 | I66: 200406261760 | J66: 1.7618203e+11 | K66: 1.6032165e+11
A67: 42433 | B67: 7684.92 | C67: 7735.55 | D67: 7321.56 | E67: 7418.8 | I67: 176786644992 | J67: 186840440832 | K67: 1.6259322e+11
A68: 42436 | B68: 7494.04 | C68: 7670.96 | D68: 7494.04 | E68: 7600.44 | I68: 140232208384 | J68: 1.7247504e+11 | K68: 1.6381043e+11
A69: 42437 | B69: 7585.86 | C69: 7670.99 | D69: 7276.67 | E69: 7670.69 | I69: 165230014464 | J69: 1.6074962e+11 | K69: 1.6542485e+11
A70: 42438 | B70: 7486.95 | C70: 7634 | D70: 7430.43 | E70: 7500.17 | I70: 131949670400 | J70: 145803964416 | K70: 165740197888
A71: 42439 | B71: 7503.42 | C71: 7568.24 | D71: 7364.29 | E71: 7376.7 | I71: 116041793536 | J71: 137740492800 | K71: 1.6414423e+11
... A378: 42900 | B378: 7346.52 | C378: 7382.58 | D378: 7340.7 | E378: 7362.86 | I378: 96077209600 | J378: 9.0051005e+10 | K378: 88425385984
...

Sheet 以前300和1000统计
A1: 交易时间 | C1: 1000
A2: 42334
A3: 42335
A4: 42338
A5: 42339
A6: 42340
A7: 42341
A8: 42342
A9: 42345
A10: 42346
A11: 42347
A12: 42348
A13: 42349
... A378: 42900
A379: 42901 | E379: 1000 | H379: 300
A380: 42902
A381: 42905
A382: 42906 | D382: 174 | E382: 7 | H382: 33 | I382: 5
A383: 42907 | C383: 158.5 | D383: 157 | E383: 7 | H383: 59 | I383: 3
A384: 42908 | C384: 106.33333 | D384: 38 | E384: 36 | G384: 38.333333 | H384: 36 | I384: 5
A385: 42909 | C385: 56.666667 | D385: 59 | E385: 41 | G385: 48.666667 | H385: 63 | I385: 4
A386: 42912 | C386: 49.666667 | D386: 141 | E386: 12 | G386: 67.333333 | H386: 115 | I386: 3
A387: 42913 | C387: 90.333333 | D387: 135 | E387: 11 | G387: 74 | H387: 56 | I387: 5
A388: 42914 | C388: 91.333333 | D388: 69 | E388: 48 | G388: 63.666667 | H388: 36 | I388: 8
A389: 42915 | C389: 20 | D389: 30 | E389: 115 | G389: 44.666667 | H389: 61 | I389: 6
A390: 42916 | C390: 2 | D390: 116 | E390: 46 | G390: 39 | H390: 44 | I390: 10
A391: 42919 | C391: 64.666667 | D391: 219 | E391: 10 | G391: 45 | H391: 55 | I391: 9
A392: 42920 | C392: 118.33333 | D392: 108 | E392: 32 | G392: 30 | H392: 27 | I392: 17
A393: 42921 | C393: 160.33333 | D393: 207 | E393: 11 | G393: 31.333333 | H393: 42 | I393: 4
A394: 42922 | C394: 148 | D394: 208 | E394: 36 | G394: 16 | H394: 9 | I394: 9
A395: 42923 | C395: 69 | D395: 48 | E395: 209 | G395: 26.333333 | H395: 58 | I395: 17
... A758: 43462 | C758: -385.33333 | D758: 20 | E758: 308 | G758: -96.666667 | H758: 15 | I758: 57
A759: 43467 | B759: 4408.53 | C759: -383 | D759: 24 | E759: 346 | G759: -90 | H759: 11 | I759: 114
A760: 43468 | B760: 4376.86 | C760: -308.66667 | D760: 25 | E760: 341 | G760: -78 | H760: 8 | I760: 97
A761: 43469 | B761: 4497.89 | C761: -189.66667 | D761: 77 | E761: 8 | G761: -53.666667 | H761: 37 | I761: 6
A762: 43472 | B762: 4594.15 | C762: -40 | D762: 133 | E762: 6 | G762: -7.6666667 | H762: 39 | I762: 4
A763: 43473 | B763: 4585.03 | C763: 82 | D763: 64 | E763: 14 | G763: 23.333333 | H763: 18 | I763: 14
A764: 43474 | B764: 4594.74 | C764: 76.666667 | D764: 59 | E764: 6 | G764: 17.333333 | H764: 16 | I764: 3
A765: 43475 | B765: 4582.48 | C765: 48.333333 | D765: 62 | E765: 20 | G765: 6.6666667 | H765: 12 | I765: 9
A766: 43476 | B766: 4621.61 | C766: 60 | D766: 104 | E766: 19 | G766: 11.333333 | H766: 26 | I766: 8
...

Sheet Sheet3
A2: 交易时间
B3: 1000
A64: 43458 | B64: -175.33333 | C64: 4558.32
A65: 43459 | B65: -234.33333 | C65: 4514.62
A66: 43460 | B66: -241.66667 | C66: 4494.5
A67: 43461 | B67: -404.33333 | C67: 4424.65
A68: 43462 | B68: -385.33333 | C68: 4430.02
A69: 43467 | B69: -383 | C69: 4408.53
A70: 43468 | B70: -308.66667 | C70: 4376.86
A71: 43469 | B71: -189.66667 | C71: 4497.89
A72: 43472 | B72: -40 | C72: 4594.15
A73: 43473 | B73: 82 | C73: 4585.03
A74: 43474 | B74: 76.666667 | C74: 4594.74
A75: 43475 | B75: 48.333333 | C75: 4582.48
... A191: 43651 | B191: 77.333333 | C191: 5424.25
A192: 43654 | B192: 149.33333 | C192: 5244.27 | D192: 1
A193: 43655 | B193: 82.666667 | C193: 5260.34
A194: 43656 | B194: -30 | C194: 5214.64
A195: 43657 | B195: -199 | C195: 5206.4
A196: 43658 | B196: -189 | C196: 5219.19
A197: 43661 | B197: -94.333333 | C197: 5273.81
A198: 43662 | B198: -21 | C198: 5285.23
A199: 43663 | B199: 8.6666667 | C199: 5289.42
A200: 43664 | B200: -110.66667 | C200: 5194.6
A201: 43665 | B201: -138.66667 | C201: 5220.03
A202: 43668 | B202: -317 | C202: 5073.33
A203: 43669 | B203: -211.33333 | C203: 5131.1
A204: 43670 | B204: -180.66667 | C204: 5194.83
... A382: 43938 | B382: 56.666667 | C382: 5710.05
A383: 43941 | B383: 99.333333 | C383: 5803.4 | D383: 1
A384: 43942 | B384: 88 | C384: 5773.01
A385: 43943 | B385: 115.66667 | C385: 5826.56
A386: 43944 | B386: 72.333333 | C386: 5789.48
A387: 43945 | B387: 15.333333 | C387: 5675.51
A388: 43948 | B388: -73.666667 | C388: 5645.66
A389: 43949 | B389: -194 | C389: 5561.2
A390: 43950 | B390: -209.33333 | C390: 5547.63
A391: 43951 | B391: -135.66667 | C391: 5678.17
A392: 43957 | B392: 25 | C392: 5802.42
A393: 43958 | B393: 114.33333 | C393: 5795.87
...

Sheet Sheet5
C1: 每次盈亏
A2: 7633.7204 | B2: 8826.0141 | C2: 0.15618775
A3: 8361.4799 | B3: 9446.8236 | C3: 0.12980283
A4: 10762.331 | B4: 12151.38 | C4: 0.12906582
A5: 7873.8227 | B5: 8877.9937 | C5: 0.12753284
A6: 12097.541 | B6: 13423.876 | C6: 0.10963672
A7: 11906.543 | B7: 12927.101 | C7: 0.085714002
A8: 8798.7154 | B8: 9523.0461 | C8: 0.082322324
A9: 9801.8264 | B9: 10605.258 | C9: 0.081967509
A10: 7165.1991 | B10: 7618.5122 | C10: 0.063265949
A11: 11507.406 | B11: 12175.313 | C11: 0.058041418
A12: 8552.3547 | B12: 9019.8226 | C12: 0.054659545 | J12: 每次亏钱 | K12: 20涨跌幅 | L12: 1
A13: 8010.7532 | B13: 8433.4534 | C13: 0.052766607 | J13: 0.037000783 | K13: -0.18433939 | L13: 1
A14: 9677.8104 | B14: 10146.838 | C14: 0.048464237 | J14: -0.035759836 | K14: -0.1525801 | L14: 1
A15: 7734.1764 | B15: 8095.0294 | C15: 0.046656936 | J15: -0.031206337 | K15: -0.15154671 | L15: 1
A16: 7821.752 | B16: 8165.8123 | C16: 0.043987626 | J16: -0.019385837 | K16: -0.11632688 | L16: 1
A17: 8029.6779 | B17: 8363.2792 | C17: 0.041546041 | J17: -0.012556033 | K17: -0.11410713 | L17: 1
A18: 7793.7017 | B18: 8094.303 | C18: 0.038569783 | J18: 0.028017254 | K18: -0.096309433 | L18: 1.0280173
A19: 11998.807 | B19: 12442.772 | C19: 0.037000783 | J19: 0.0029918588 | K19: -0.085989936 | L19: 1.0310929
A20: 10389.256 | B20: 10762.331 | C20: 0.035909725 | J20: -0.0043956015 | K20: -0.075176339 | L20: 1.0265607
A21: 8173.3793 | B21: 8461.9798 | C21: 0.035309817 | J21: 0.12980283 | K21: -0.065221226 | L21: 1.1598111
A22: 7769.0985 | B22: 8029.6779 | C22: 0.033540492 | J22: -0.029078136 | K22: -0.064653119 | L22: 1.126086
A23: 9305.5954 | B23: 9566.3126 | C23: 0.028017254 | J23: 0.0062589791 | K23: -0.063871288 | L23: 1.1331341
A24: 9566.3126 | B24: 9768.6151 | C24: 0.021147376 | J24: -0.0094109151 | K24: -0.062722504 | L24: 1.1224703
... A104: 8683.7066 | B104: 8173.3793 | C104: -0.058768377 | J104: -0.045211222 | K104: 0.039156925 | L104: 1.9712714
J105: 0.035309817 | K105: 0.041687034 | L105: 2.0408766
J106: 0.046656936 | K106: 0.047189315 | L106: 2.1360976 | M106: 前期20天涨跌幅 | N106: 波段盈亏平均
J107: -0.018712859 | K107: 0.048579627 | L107: 2.0961252 | M107: 跌10%以上的 | N107: -0.013
J108: 0.0078728436 | K108: 0.048937059 | L108: 2.1126276 | M108: 跌5-10%之间 | N108: 0.006
J109: -0.048385901 | K109: 0.049252263 | L109: 2.0104062 | M109: 跌5%y以内 | N109: 0.008
J110: -0.004234231 | K110: 0.061790237 | L110: 2.0104062 | M110: 涨5%以内 | N110: 0.006
J111: -0.020270036 | K111: 0.062911317 | L111: 2.0104062 | M111: 涨5%以上 | N111: -0.018
J112: -0.010933992 | K112: 0.065514784 | L112: 2.0104062
J113: -0.0063876004 | K113: 0.070645136 | L113: 2.0104062
J114: -0.028419273 | K114: 0.082404473 | L114: 2.0104062
J115: -0.039752416 | K115: 0.089755715 | L115: 2.0104062
J124: 每次亏钱 | K124: 5天涨跌幅
J125: -0.031206337 | K125: -0.11570684 | M125: 前期5天涨跌幅 | N125: 波段盈亏平均
J126: -0.058768377 | K126: -0.1155303 | M126: 跌10%以上的 | N126: -0.017
J127: 0.037000783 | K127: -0.10642188 | M127: 跌5-10%之间 | N127: -0.018
...

Sheet Sheet4
A1: -0.12438727
A2: -0.12153375
A3: -0.10853003
A4: -0.10612359 | G4: -0.12438727
A5: -0.096279503 | G5: -0.10853003
A6: -0.091913572 | G6: -0.10612359
A7: -0.088710968 | G7: -0.091913572
A8: -0.088271668 | G8: -0.088710968
A9: -0.085437646 | G9: -0.079949215
A10: -0.079949215 | G10: -0.075148431
A11: -0.079897998 | G11: -0.069339452
A12: -0.075148431 | G12: -0.066812154 | L12: 连续2天涨跌幅
A13: -0.073997465 | G13: -0.065069409 | L13: -5%以上的 | M13: 41 | P13: 全部时间占比 | Q13: 做空阶段 | S13: 全部时间占比 | T13: 做空阶段
A14: -0.069339452 | G14: -0.064525451 | L14: -5和-4% | M14: 110 | O14: 跌幅大于-5% | P14: 41 | Q14: 24 | R14: 跌幅大于-5% | S14: =P14/2003 -> 0.020469296 | T14: =Q14/635 -> 0.037795276
A15: -0.067472838 | G15: -0.057425474 | O15: -5%和-4% | P15: 110 | Q15: 9 | R15: -5%和-4% | S15: =P15/2003 -> 0.054917624 | T15: =Q15/635 -> 0.014173228
A16: -0.066812154 | G16: -0.057320511 | O16: -4%和-3% | P16: 83 | Q16: 38 | R16: -4%和-3% | S16: =P16/2003 -> 0.041437843 | T16: =Q16/635 -> 0.05984252
A17: -0.066055759 | G17: -0.056981752 | O17: -3%和-2% | P17: 134 | Q17: 57 | R17: -3%和-2% | S17: =P17/2003 -> 0.066899651 | T17: =Q17/635 -> 0.08976378
A18: -0.065069409 | G18: -0.056759514 | O18: -2%和-1% | P18: 287 | Q18: 114 | R18: -2%和-1% | S18: =P18/2003 -> 0.14328507 | T18: =Q18/635 -> 0.17952756
A19: -0.064525451 | G19: -0.055811619 | O19: -1%和0% | P19: 390 | Q19: 127 | R19: -1%和0% | S19: =P19/2003 -> 0.19470794 | T19: =Q19/635 -> 0.2
A20: -0.057425474 | G20: -0.054928821 | O20: 0和1% | P20: 404 | Q20: 108 | R20: 0和1% | S20: =P20/2003 -> 0.20169745 | T20: =Q20/635 -> 0.17007874
A21: -0.057320511 | G21: -0.053206985 | O21: 1%和2% | P21: 341 | Q21: 86 | R21: 1%和2% | S21: =P21/2003 -> 0.17024463 | T21: =Q21/635 -> 0.13543307
A22: -0.056981752 | G22: -0.051842968 | O22: 2%和3% | P22: 158 | Q22: 45 | R22: 2%和3% | S22: =P22/2003 -> 0.078881677 | T22: =Q22/635 -> 0.070866142
A23: -0.056963194 | G23: -0.051513052 | O23: 3%和4% | P23: 75 | Q23: 19 | R23: 3%和4% | S23: =P23/2003 -> 0.037443834 | T23: =Q23/635 -> 0.02992126
A24: -0.056759514 | G24: -0.051140914 | O24: 4%和5% | P24: 34 | Q24: 6 | R24: 4%和5% | S24: =P24/2003 -> 0.016974538 | T24: =Q24/635 -> 0.0094488189
A25: -0.056393286 | G25: -0.051001821 | O25: 大于5% | P25: 27 | Q25: 2 | R25: 大于5% | S25: =P25/2003 -> 0.01347978 | T25: =Q25/635 -> 0.0031496063
A26: -0.055811619 | G26: -0.050968669
A27: -0.054928821 | G27: -0.050885886
A28: -0.054374057 | G28: -0.047022751
A29: -0.054234222 | G29: -0.046976002
A30: -0.054101136 | G30: -0.044638426
A31: -0.053886158 | G31: -0.044616288
A32: -0.053206985 | G32: -0.04342112
A33: -0.052817265 | G33: -0.041552845
A34: -0.051842968 | G34: -0.041405702
A35: -0.051513052 | G35: -0.041089306
A36: -0.051140914 | G36: -0.040883579
A37: -0.051113025 | G37: -0.039747935
... A378: -0.015842857 | G378: 0.00058844316
A379: -0.015825098 | C379: 持股阶段涨跌幅 | G379: 0.00067604073
A380: -0.01579397 | G380: 0.0007126253
...

Sheet Sheet2
B1: 做空择时 | C1: 现金流择时 | D1: 1000不做空就现金流择时
A2: 43082 | B2: 7372.3291 | C2: 1998.036 | D2: =C2 -> 1998.036
A3: 43083 | B3: 7372.3291 | C3: 1990.13 | D3: =IF(B3=B2,D2*C3/C2,D2) -> 1990.13
A4: 43084 | B4: 7372.3291 | C4: 1971.878 | D4: =IF(B4=B3,D3*C4/C3,D3) -> 1971.878
A5: 43087 | B5: 7372.3291 | C5: 1971.878 | D5: =IF(B5=B4,D4*C5/C4,D4) -> 1971.878
A6: 43088 | B6: 7330.6741 | C6: 1971.878 | D6: =IF(B6=B5,D5*C6/C5,D5) -> 1971.878
A7: 43089 | B7: 7407.2687 | C7: 1971.878 | D7: =IF(B7=B6,D6*C7/C6,D6) -> 1971.878
A8: 43090 | B8: 7396.9175 | C8: 1971.878 | D8: =IF(B8=B7,D7*C8/C7,D7) -> 1971.878
A9: 43091 | B9: 7411.5407 | C9: 1971.878 | D9: =IF(B9=B8,D8*C9/C8,D8) -> 1971.878
A10: 43094 | B10: 7513.5818 | C10: 1971.878 | D10: =IF(B10=B9,D9*C10/C9,D9) -> 1971.878
A11: 43095 | B11: 7480.8449 | C11: 1971.878 | D11: =IF(B11=B10,D10*C11/C10,D10) -> 1971.878
A12: 43096 | B12: 7511.1193 | C12: 1971.878 | D12: =IF(B12=B11,D11*C12/C11,D11) -> 1971.878
A13: 43097 | B13: 7496.0376 | C13: 1971.878 | D13: =IF(B13=B12,D12*C13/C12,D12) -> 1971.878
A14: 43098 | B14: 7430.4464 | C14: 1971.878 | D14: =IF(B14=B13,D13*C14/C13,D13) -> 1971.878
... A1892: 45924 | B1892: 21726.565 | C1892: 6464.7976 | D1892: =IF(B1892=B1891,D1891*C1892/C1891,D1891) -> 6688.3866
C1893: 6464.7976 | D1893: =IF(B1893=B1892,D1892*C1893/C1892,D1892) -> 6688.3866
C1894: 6464.7976 | D1894: =IF(B1894=B1893,D1893*C1894/C1893,D1893) -> 6688.3866
C1895: 6464.7976 | D1895: =IF(B1895=B1894,D1894*C1895/C1894,D1894) -> 6688.3866
C1896: 6464.7976 | D1896: =IF(B1896=B1895,D1895*C1896/C1895,D1895) -> 6688.3866
C1897: 6464.7976 | D1897: =IF(B1897=B1896,D1896*C1897/C1896,D1896) -> 6688.3866
C1898: 6413.7269 | D1898: =IF(B1898=B1897,D1897*C1898/C1897,D1897) -> 6635.5496
C1899: 6393.7969 | D1899: =IF(B1899=B1898,D1898*C1899/C1898,D1898) -> 6614.9303
C1900: 6457.3238 | D1900: =IF(B1900=B1899,D1899*C1900/C1899,D1899) -> 6680.6544
C1901: 6421.2007 | D1901: =IF(B1901=B1900,D1900*C1901/C1900,D1900) -> 6643.2819
C1902: 6282.9362 | D1902: =IF(B1902=B1901,D1901*C1902/C1901,D1901) -> 6500.2355
C1903: 6317.8137 | D1903: =IF(B1903=B1902,D1902*C1903/C1902,D1902) -> 6536.3192
C1904: 6317.8137 | D1904: =IF(B1904=B1903,D1903*C1904/C1903,D1903) -> 6536.3192
... C1912: 6448.6889 | D1912: =IF(B1912=B1911,D1911*C1912/C1911,D1911) -> 6671.7208

Sheet Sheet6
J1: 净值 | K1: 跌多不做净值 | L1: 跌多反做净值
A2: 每次盈亏 | B2: 10天涨幅 | G2: 开仓到最大下跌 | H2: 收益 | J2: 1 | K2: 1 | L2: 1
G3: -0.15066393 | H3: -0.031206337 | I3: 0 | J3: 0.96879366 | K3: 1 | L3: 1.0322115
G4: -0.12673828 | H4: -0.058768377 | I4: 0 | J4: 0.91185923 | K4: 1 | L4: 1.0966605
G5: -0.10642188 | H5: 0.037000783 | I5: 0 | J5: 0.94559874 | K5: 1 | L5: 1.057531
A6: -0.021659656 | B6: -0.064821928 | G6: -0.094719227 | H6: -0.012556033 | I6: 0 | J6: 0.93372577 | K6: 1 | L6: 1.0709783
G7: -0.091875525 | H7: -0.045211222 | I7: 0 | J7: 0.89151089 | K7: 1 | L7: 1.1216913
G8: -0.084642988 | H8: -0.0064338617 | I8: 0 | J8: 0.88577503 | K8: 1 | L8: 1.1289548
G9: -0.083374246 | H9: -0.026595436 | I9: 0 | J9: 0.86221746 | K9: 1 | L9: 1.1598002
G10: -0.076642158 | H10: -0.0094109151 | I10: 0 | J10: 0.8541032 | K10: 1 | L10: 1.1708187
G11: -0.076032779 | H11: -0.039752416 | I11: 0 | J11: 0.82015053 | K11: 1 | L11: 1.2192884
G12: -0.072953076 | H12: -0.045569334 | I12: 0 | J12: 0.78277682 | K12: 1 | L12: 1.2775033
G13: -0.07253418 | H13: -0.01668527 | I13: 0 | J13: 0.76971598 | K13: 1 | L13: 1.2991805
G14: -0.071935253 | H14: 0.0029918588 | I14: 0 | J14: 0.77201886 | K14: 1 | L14: 1.2953051
G15: -0.070601101 | H15: -0.029078136 | I15: 0 | J15: 0.74956999 | K15: 1 | L15: 1.3340982
G16: -0.069430922 | H16: -0.053693483 | I16: 0 | J16: 0.70932297 | K16: 1 | L16: 1.409795
G17: -0.065784655 | H17: -0.048385901 | I17: 0 | J17: 0.67500174 | K17: 1 | L17: 1.4814777
G18: -0.064309973 | H18: -0.029214324 | I18: 0 | J18: 0.65528202 | K18: 1 | L18: 1.5260605
... G20: -0.062470536 | H20: -0.020270036 | I20: 0 | J20: 0.63531151 | K20: 1 | L20: 1.574031
G21: -0.05864154 | H21: 0.035309817 | I21: 0.035309817 | J21: 0.65774425 | K21: 1.0353098 | L21: 1.5203478 | O21: 平均
G22: -0.053657948 | H22: -0.054513081 | I22: -0.054513081 | J22: 0.62188858 | K22: 0.97887189 | L22: 1.6080051 | N22: 跌 4 到6 | O22: 0.02
G23: -0.053343913 | H23: -0.0040091952 | I23: -0.0040091952 | J23: 0.61939531 | K23: 0.9749474 | L23: 1.6144778 | N23: 跌 2到 4 | O23: 0.01
G24: -0.050662425 | H24: -0.00067699835 | I24: -0.00067699835 | J24: 0.61897598 | K24: 0.97428736 | L24: 1.6155716 | N24: 跌2以内 | O24: 0.02
G25: -0.05023589 | H25: -0.026036388 | I25: -0.026036388 | J25: 0.60286008 | K25: 0.94892044 | L25: 1.6587597
G26: -0.049447693 | H26: 0.028017254 | I26: 0.028017254 | J26: 0.61975056 | K26: 0.97550658 | L26: 1.7052336
G27: -0.04928412 | H27: 0.12980283 | I27: 0.12980283 | J27: 0.70019594 | K27: 1.1021301 | L27: 1.9265777
G28: -0.049034197 | H28: -0.01425928 | I28: -0.01425928 | J28: 0.69021165 | K28: 1.0864145 | L28: 1.8991061
G29: -0.048946365 | H29: 0.041546041 | I29: 0.041546041 | J29: 0.71888721 | K29: 1.1315507 | L29: 1.9780065
G30: -0.045632384 | H30: -0.015018833 | I30: -0.015018833 | J30: 0.70809036 | K30: 1.1145562 | L30: 1.9482991
G31: -0.045623282 | H31: -0.035759836 | I31: -0.035759836 | J31: 0.68276917 | K31: 1.0746998 | L31: 1.8786283
G32: -0.044340807 | H32: -0.028419273 | I32: -0.028419273 | J32: 0.66336537 | K32: 1.0441576 | L32: 1.825239
G33: -0.044073557 | H33: 0.085714002 | I33: 0.085714002 | J33: 0.72022507 | K33: 1.1336566 | L33: 1.9816875
G34: -0.043971463 | H34: 0.008069698 | I34: 0.008069698 | J34: 0.72603706 | K34: 1.1428048 | L34: 1.9976792
G35: -0.042896524 | H35: -0.0098440665 | I35: -0.0098440665 | J35: 0.71888991 | K35: 1.131555 | L35: 1.9780139
G36: -0.042444746 | H36: 0.009212438 | I36: 0.009212438 | J36: 0.72551264 | K36: 1.1419794 | L36: 1.9962362
... G52: -0.033537785 | H52: 0.01981222 | I52: 0.01981222 | J52: 1.1017253 | K52: 1.7341498 | L52: 3.0313793
A53: 收益 | B53: 前十天涨跌幅 | G53: -0.03262534 | H53: -0.0060478422 | I53: -0.0060478422 | J53: 1.0950623 | K53: 1.7236619 | L53: 3.013046
G54: -0.031047479 | H54: -0.0065042805 | I54: -0.0065042805 | J54: 1.0879397 | K54: 1.7124507 | L54: 2.9934483
A55: -0.018712859 | B55: 0.0013943461 | G55: -0.030080933 | H55: -0.0043956015 | I55: -0.0043956015 | J55: 1.0831575 | K55: 1.7049235 | L55: 2.9802903
G56: -0.029794972 | H56: 0.00082640969 | I56: 0.00082640969 | J56: 1.0840526 | K56: 1.7063325 | L56: 2.9827532
...

Sheet Sheet7
A1: 收益 | B1: 前十天涨跌幅 | I1: 开仓到最大下跌 | J1: 收益
A2: -0.018712859 | B2: 0.0013943461 | I2: -0.023690155 | J2: 0.0063280409
A3: 0.0063280409 | B3: 0.0075946524
A4: -0.0060478422 | B4: -0.031323893
A5: -0.00067699835 | B5: -0.034283936
A6: 0.0029918588 | B6: -0.068909852
A7: -0.002851542 | B7: -0.008947092
A8: 0.063265949 | B8: -0.02187139
A9: -0.0061225649 | B9: -0.006805929
A10: 0.0081687947 | B10: 0.0050341996
A11: 0.15618775 | B11: -0.014362408 | I11: -0.03262534 | J11: -0.0060478422
A12: -0.035759836 | B12: -0.019104218
A13: 0.01344403 | B13: -0.015927438
A14: 0.0003441968 | B14: -0.039243358
A15: 0.01981222 | B15: -0.0051591103
A16: 0.082322324 | B16: -0.002655457
A17: -0.031206337 | B17: -0.14703245
A18: -0.019385837 | B18: -0.024969652
A19: -0.020270036 | B19: -0.013543807
A20: -0.048385901 | B20: -0.05209101
A21: -0.018459334 | B21: 0.0092560421
A22: 0.0083295327 | B22: -0.0013532178
A23: -0.029214324 | B23: -0.052170715
... A25: 0.12753284 | B25: -0.013201384
A26: -0.0043956015 | B26: -0.010931368 | I26: -0.050662425 | J26: -0.00067699835
A27: -0.014222381 | B27: -0.017923643
A28: -0.01425928 | B28: -0.025554108
A29: -0.0042681068 | B29: -0.038816664 | I29: -0.071935253 | J29: 0.0029918588
A30: 0.054659545 | B30: -0.0041138875
A31: -0.029078136 | B31: -0.066482
A32: 0.0078728436 | B32: -0.034367664
A33: -0.0154889 | B33: 0.019677427
A34: 0.010521415 | B34: 0.0040923833
A35: -0.011103167 | B35: -0.026432885
A36: -0.058768377 | B36: -0.11137086
A37: 0.035309817 | B37: 0.012687852
A38: -0.0065042805 | B38: 0.011973772
A39: 0.0047002414 | B39: -0.00072983003
A40: -0.039752416 | B40: -0.083284142
A41: -0.0098440665 | B41: 0.0092140991
...
